Workbook

Sheet Instructions
B2: This Google Sheet is used to enter the sandwich counts by location for each week in the year. It contains weekly sandwich data from mid April 2020 to present.
B4: There are 54 tabs on the sheet: Instructions (this tab), InputData, ByLocation, and ByWeekOfYear
B5: 1 | C5: Instructions: | D5: This tab describes the purpose, structure and use of the Sheet
B6: 2 | C6: InputData: | D6: This tab is used to enter each weeks sandwich counts for each location
D7: To enter data, go to the first blank row at the bottom of the table. It is important NOT to leave any blank rows!
E8: Double click in column A to open a date picker and select the appropriate data. Alternately you can type the date in the same format as the existing data.
E9: Double click on Column B and select the Location. Alternately just start typing the Location name and you will be presented with possible Locations. Select the appropriate one.
E10: In Column C enter the number of Sandwiches.
E11: If you have more data to enter go to the next row and repeat the process
B12: 3 | C12: ByLocation: | D12: This tab is a report that duplicates the original Sandwich Totals sheet
D13: The report will automatically update when new data is entered on the input sheet. DO NOT enter any data on this sheet!
D14: The Locations labled as Previous are hidden to make the report more readable.
B15: 4 | C15: ByWeekOfYear: | D15: This tab is a report of the sandwich counts by week for each year.
D16: The report will automatically update when new data is entered on the input sheet. DO NOT enter any data on this sheet! (except in the Events table.)
D17: This tab also has the weekly average numbers for each year and a manually created list of signifcant events and the week in which they occur. This table can be added to as desired. It does not effect the report.
D18: The data on the report is formatted to show values greater than the weekly avarage for the year in Green and less than the weekly average for the year in Red.
E19: The intent of the formatting is to help predict if the future weeks will be "Up or Down" from the current weekly average, based on past years' performance for the same week of the year.
D20: There is also a Slicer called Location in the upper right of the sheet. This allows you to select a location (or group of locations) to filter the data for your selection. To return to all of the data click the Select All choice in the dropdown.
B21: 5 | C21: Dashboard | D21: This tab shows key metrics and charts. This should update automatically as new data is entered.
B23: Development Notes:
C24: Sheet developed by Scott Bangert June 2025 | F24: scott.bangert@icloud.com

Sheet InputData
A1: Date | B1: Location | C1: Sandwiches | D1: WeekOfYear | E1: WeekOfProgram | F1: Year | G1: Column 1
A2: 43943 | B2: GROUPS Numbers displayed only when not included in a host's count. | C2: 317 | D2: {=IF(A2:A3663 = "" , , WEEKNUM(A2:A3663) )} -> 17 | E2: {=IF(A2:A3663 = "" , , WEEKNUM(A2:A3663)-16 + (YEAR(A2:A3663)-2020) * 53 )} -> 1 | F2: {=IF(A2:A3663 = "" , , YEAR(A2:A3663) )} -> 2020
A3: 43950 | B3: GROUPS Numbers displayed only when not included in a host's count. | C3: 530 | D3: 18 | E3: 2 | F3: 2020
A4: 43957 | B4: GROUPS Numbers displayed only when not included in a host's count. | C4: 290 | D4: 19 | E4: 3 | F4: 2020
A5: 43964 | B5: GROUPS Numbers displayed only when not included in a host's count. | C5: 430 | D5: 20 | E5: 4 | F5: 2020
A6: 43971 | B6: GROUPS Numbers displayed only when not included in a host's count. | C6: 581 | D6: 21 | E6: 5 | F6: 2020
A7: 43978 | B7: GROUPS Numbers displayed only when not included in a host's count. | C7: 432 | D7: 22 | E7: 6 | F7: 2020
A8: 43985 | B8: GROUPS Numbers displayed only when not included in a host's count. | C8: 780 | D8: 23 | E8: 7 | F8: 2020
A9: 43992 | B9: GROUPS Numbers displayed only when not included in a host's count. | C9: 939 | D9: 24 | E9: 8 | F9: 2020
A10: 43999 | B10: GROUPS Numbers displayed only when not included in a host's count. | C10: 995 | D10: 25 | E10: 9 | F10: 2020
A11: 44006 | B11: GROUPS Numbers displayed only when not included in a host's count. | C11: 1177 | D11: 26 | E11: 10 | F11: 2020
A12: 44013 | B12: GROUPS Numbers displayed only when not included in a host's count. | C12: 626 | D12: 27 | E12: 11 | F12: 2020
A13: 44020 | B13: GROUPS Numbers displayed only when not included in a host's count. | C13: 866 | D13: 28 | E13: 12 | F13: 2020
A14: 44027 | B14: GROUPS Numbers displayed only when not included in a host's count. | C14: 1231 | D14: 29 | E14: 13 | F14: 2020
... A1466: 45686 | B1466: ALPHARETTA ( Karen, Nancy, Carrey, Kelly, Jason) | C1466: 936 | D1466: 5 | E1466: 254 | F1466: 2025
A1467: 45686 | B1467: DUNWOODY/PTC (Marcy, Lisa, Darren, Renee, Suzanna, Sonika, Tracie) | C1467: TBD | D1467: 5 | E1467: 254 | F1467: 2025
A1468: 45686 | B1468: E COBB/ROSWELL (Natalie, Silke, Vicki, Rachel, Judy, Jenny) | C1468: 1890 | D1468: 5 | E1468: 254 | F1468: 2025
A1469: 45686 | B1469: FLOWERY BRANCH (Kristina) | C1469: 402 | D1469: 5 | E1469: 254 | F1469: 2025
A1470: 45686 | B1470: GROUPS Numbers displayed only when not included in a host's count. | C1470: 7140 | D1470: 5 | E1470: 254 | F1470: 2025
A1471: 45686 | B1471: INTOWN/DRUID HILLS (Laura, Jordan, Angie, Della, Julie, Ashley) | C1471: 1992 | D1471: 5 | E1471: 254 | F1471: 2025
A1472: 45686 | B1472: SANDY SPRINGS (Allison, Jen, Terri, Sarah, Kate) | C1472: 706 | D1472: 5 | E1472: 254 | F1472: 2025
A1473: 45693 | B1473: ALPHARETTA ( Karen, Nancy, Carrey, Kelly, Jason) | C1473: 1252 | D1473: 6 | E1473: 255 | F1473: 2025
A1474: 45693 | B1474: Collective Learning | C1474: 50 | D1474: 6 | E1474: 255 | F1474: 2025
A1475: 45693 | B1475: DUNWOODY/PTC (Marcy, Lisa, Darren, Renee, Suzanna, Sonika, Tracie) | C1475: 2173 | D1475: 6 | E1475: 255 | F1475: 2025
A1476: 45693 | B1476: E COBB/ROSWELL (Natalie, Silke, Vicki, Rachel, Judy, Jenny) | C1476: 1265 | D1476: 6 | E1476: 255 | F1476: 2025
A1477: 45693 | B1477: GROUPS Numbers displayed only when not included in a host's count. | C1477: 2600 | D1477: 6 | E1477: 255 | F1477: 2025
A1478: 45693 | B1478: INTOWN/DRUID HILLS (Laura, Jordan, Angie, Della, Julie, Ashley) | C1478: 854 | D1478: 6 | E1478: 255 | F1478: 2025
A1479: 45693 | B1479: SANDY SPRINGS (Allison, Jen, Terri, Sarah, Kate) | C1479: 549 | D1479: 6 | E1479: 255 | F1479: 2025
... A1635: 45834 | B1635: FLOWERY BRANCH (Kristina) | C1635: 300 | D1635: 26 | E1635: 275 | F1635: 2025
A1636: 45834 | B1636: GROUPS | C1636: 1312 | D1636: 26 | E1636: 275 | F1636: 2025 | G1636: NCL
A1637: 45834 | B1637: GROUPS Numbers displayed only when not included in a host's count. | C1637: 3260 | D1637: 26 | E1637: 275 | F1637: 2025
A1638: 45834 | B1638: INTOWN/DRUID HILLS (Laura, Jordan, Angie, Della, Julie, Ashley) | C1638: 1047 | D1638: 26 | E1638: 275 | F1638: 2025
A1639: 45834 | B1639: SANDY SPRINGS (Allison, Jen, Terri, Sarah, Kate) | C1639: 667 | D1639: 26 | E1639: 275 | F1639: 2025
A1640: 45847 | B1640: ALPHARETTA ( Karen, Nancy, Carrey, Kelly, Jason) | C1640: 1185 | D1640: 28 | E1640: 277 | F1640: 2025
A1641: 45847 | B1641: Collective Learning | C1641: 250 | D1641: 28 | E1641: 277 | F1641: 2025
A1642: 45847 | B1642: DUNWOODY/PTC (Marcy, Lisa, Darren, Renee, Suzanna, Sonika, Tracie) | C1642: 1240 | D1642: 28 | E1642: 277 | F1642: 2025
A1643: 45847 | B1643: E COBB/ROSWELL (Natalie, Silke, Vicki, Rachel, Judy, Jenny) | C1643: 2237 | D1643: 28 | E1643: 277 | F1643: 2025
A1644: 45847 | B1644: FLOWERY BRANCH (Kristina) | C1644: 285 | D1644: 28 | E1644: 277 | F1644: 2025
A1645: 45847 | B1645: INTOWN/DRUID HILLS (Laura, Jordan, Angie, Della, Julie, Ashley) | C1645: 528 | D1645: 28 | E1645: 277 | F1645: 2025
A1646: 45847 | B1646: SANDY SPRINGS (Allison, Jen, Terri, Sarah, Kate) | C1646: 350 | D1646: 28 | E1646: 277 | F1646: 2025
...

Sheet ByLocation

Sheet Detail18-275-6262025
A1: Date | B1: Location | C1: Sandwiches | D1: WeekOfYear | E1: WeekOfProgram | F1: Year | G1: Column 1
A2: 45834 | B2: ALPHARETTA ( Karen, Nancy, Carrey, Kelly, Jason) | C2: 2466 | D2: 26 | E2: 275 | F2: 2025
A3: 45834 | B3: Collective Learning | C3: 300 | D3: 26 | E3: 275 | F3: 2025
A4: 45834 | B4: DUNWOODY/PTC (Marcy, Lisa, Darren, Renee, Suzanna, Sonika, Tracie) | C4: 2991 | D4: 26 | E4: 275 | F4: 2025
A5: 45834 | B5: E COBB/ROSWELL (Natalie, Silke, Vicki, Rachel, Judy, Jenny) | C5: 1960 | D5: 26 | E5: 275 | F5: 2025
A6: 45834 | B6: GROUPS Numbers displayed only when not included in a host's count. | C6: 3260 | D6: 26 | E6: 275 | F6: 2025
A7: 45834 | B7: GROUPS | C7: 1312 | D7: 26 | E7: 275 | F7: 2025
A8: 45834 | B8: SANDY SPRINGS (Allison, Jen, Terri, Sarah, Kate) | C8: 667 | D8: 26 | E8: 275 | F8: 2025

Sheet Detail17-111-5182022-GROUPS
A1: Date | B1: Location | C1: Sandwiches | D1: WeekOfYear | E1: WeekOfProgram | F1: Year | G1: Column 1
A2: 44699 | B2: GROUPS | C2: 450 | D2: 21 | E2: 111 | F2: 2022

Sheet ByWeekofYear
M4: Year | N4: 2020 | O4: 2021 | P4: 2022 | Q4: 2023 | R4: 2024 | S4: 2025 | T4: 2026
M5: Weekly Average | N5: =Average(C3:C55) -> 1184.6389 | O5: =Average(D3:D55) -> 5567.66 | P5: =Average(E3:E55) -> 8799.1837 | Q5: =Average(F3:F55) -> 10191.375 | R5: =Average(G3:G55) -> 9304.84 | S5: =Average(H3:H55) -> 9317.3548 | T5: =Average(I3:I55) -> 0
M8: Events
M9: Week of Event | N9: 2020 | O9: 2021 | P9: 2022 | Q9: 2023 | R9: 2024 | S9: 2025 | T9: 2026
M10: MLK | N10: =weeknum("1/20/2020") -> 4 | O10: =weeknum("1/18/2021") -> 4 | P10: =weeknum("1/17/2022") -> 4 | Q10: 3 | R10: 4 | S10: 4
M11: SchoolEnd | N11: =weeknum("5/24/2020") -> 22 | O11: =weeknum("5/26/2021") -> 22 | P11: =weeknum("5/26/2022") -> 22 | Q11: 21 | R11: 22 | S11: 22
M12: SchoolStart | N12: =weeknum("8/24/2020") -> 35 | O12: =weeknum("8/5/2021") -> 32 | P12: =weeknum("8/1/2022") -> 32 | Q12: 31 | R12: 31 | S12: 31
M13: Thanksgiving | N13: =weeknum("11/26/2020") -> 48 | O13: =weeknum("5/26/2021") -> 22 | P13: =weeknum("11/24/2022") -> 48 | Q13: 47 | R13: 48 | S13: 48
M14: Christmas | N14: =weeknum("12/25/2020") -> 52 | O14: =weeknum("12/25/2022") -> 53 | P14: =weeknum("12/25/2021") -> 52 | Q14: 52 | R14: 52 | S14: 52
M15: NCL
M16: Presidents Day

Sheet Dashboard
G4: Sandwiches Made Since 2020 | H4: =GETPIVOTDATA("Sandwiches",ByWeekofYear!$C$2) -> 2004432
M5: Date Current as of: | N5: =IFERROR(__xludf.DUMMYFUNCTION("QUERY(InputData!A2:F1024, ""SELECT MAX(A) WHERE F = YEAR(NOW()) GROUP BY F LABEL MAX(A) '' "" )"),45875.0) -> 45875
C27: 2022 | D27: 2023 | E27: 2024 | F27: 2025 YTD | M27: 2025
B28: Sandwich Count | C28: =GETPIVOTDATA("Sandwiches",ByWeekofYear!$A$1, "Year","2022") -> 434825 | D28: =GETPIVOTDATA("Sandwiches",ByWeekofYear!$A$1, "Year","2023") -> 489186 | E28: =GETPIVOTDATA("Sandwiches",ByWeekofYear!$A$1, "Year","2024") -> 465242 | F28: =GETPIVOTDATA("Sandwiches",ByWeekofYear!$A$1, "Year","2025") -> 288838 | M28: Location | N28: Sandwiches | O28: % of Year Total
B29: $ per Sandwich | C29: 1.3 | D29: 1.3 | E29: 1.3 | F29: 1.3 | M29: GROUPS | N29: =GETPIVOTDATA("Sandwiches",Dashboard!$R$29,"Year", "2025", "Location", "GROUPS Numbers displayed only when not included in a host's count.") -> 60675 | O29: =GETPIVOTDATA("% of Year Total",Dashboard!$R$28,"Year", "2025", "Location", "GROUPS Numbers displayed only when not included in a host's count.") -> 0.26548498
B30: Total Value | C30: =+C28*C29 -> 565272.5 | D30: =+D28*D29 -> 635941.8 | E30: =+E28*E29 -> 604814.6 | F30: =+F28*F29 -> 375489.4 | M30: DUNWOODY/PTC | N30: =GETPIVOTDATA("Sandwiches",Dashboard!$R$29,"Year", "2025", "Location", "DUNWOODY/PTC (Marcy, Lisa, Darren, Renee, Suzanna, Sonika, Tracie)") -> 38444 | O30: =GETPIVOTDATA("% of Year Total",Dashboard!$R$28,"Year", "2025", "Location", "DUNWOODY/PTC (Marcy, Lisa, Darren, Renee, Suzanna, Sonika, Tracie)") -> 0.16821269
M31: ALPHARETTA | N31: =GETPIVOTDATA("Sandwiches",Dashboard!$R$28,"Year", "2025", "Location", "ALPHARETTA ( Karen, Nancy, Carrey, Kelly, Jason)") -> 34867 | O31: =GETPIVOTDATA("% of Year Total",Dashboard!$R$28,"Year", "2025", "Location", "ALPHARETTA ( Karen, Nancy, Carrey, Kelly, Jason)") -> 0.15256143
M32: E COBB/ROSWELL | N32: =GETPIVOTDATA("Sandwiches",Dashboard!$R$28,"Year", "2025", "Location", "E COBB/ROSWELL (Natalie, Silke, Vicki, Rachel, Judy, Jenny)") -> 27976 | O32: =GETPIVOTDATA("% of Year Total",Dashboard!$R$28,"Year", "2025", "Location", "E COBB/ROSWELL (Natalie, Silke, Vicki, Rachel, Judy, Jenny)") -> 0.12240969
M33: INTOWN/DRUID HILLS | N33: =GETPIVOTDATA("Sandwiches",Dashboard!$R$28,"Year", "2025", "Location", "INTOWN/DRUID HILLS (Laura, Jordan, Angie, Della, Julie, Ashley)") -> 24824 | O33: =GETPIVOTDATA("% of Year Total",Dashboard!$R$28,"Year", "2025", "Location", "INTOWN/DRUID HILLS (Laura, Jordan, Angie, Della, Julie, Ashley)") -> 0.10861803
M34: SANDY SPRINGS | N34: =GETPIVOTDATA("Sandwiches",Dashboard!$R$28,"Year", "2025", "Location", "SANDY SPRINGS (Allison, Jen, Terri, Sarah, Kate)") -> 13201 | O34: =GETPIVOTDATA("% of Year Total",Dashboard!$R$28,"Year", "2025", "Location", "SANDY SPRINGS (Allison, Jen, Terri, Sarah, Kate)") -> 0.057761306
M35: FLOWERY BRANCH | N35: =GETPIVOTDATA("Sandwiches",Dashboard!$R$28,"Year", "2025", "Location", "FLOWERY BRANCH (Kristina)") -> 7026 | O35: =GETPIVOTDATA("% of Year Total",Dashboard!$R$28,"Year", "2025", "Location", "FLOWERY BRANCH (Kristina)") -> 0.030742439
M36: COLLECTIVE LEARNING | N36: =GETPIVOTDATA("Sandwiches",Dashboard!$R$28,"Year", "2025", "Location", "Collective Learning") -> 1825 | O36: =GETPIVOTDATA("% of Year Total",Dashboard!$R$28,"Year", "2025", "Location", "Collective Learning") -> 0.0079853332
M37: Grand Total | N37: =SUM(N29:N36) -> 208838 | O37: =SUM(O29:O36) -> 0.9137759
R56: Year | S56: Values
R57: 2025
Q58: Location | R58: Sandwiches | S58: % of Year Total
Q59: GROUPS Numbers displayed only when not included in a host's count. | R59: 63935 | S59: 0.29022052
Q60: DUNWOODY/PTC (Marcy, Lisa, Darren, Renee, Suzanna, Sonika, Tracie) | R60: 38444 | S60: 0.17450907
Q61: ALPHARETTA ( Karen, Nancy, Carrey, Kelly, Jason) | R61: 34391 | S61: 0.15611127
Q62: E COBB/ROSWELL (Natalie, Silke, Vicki, Rachel, Judy, Jenny) | R62: 32710 | S62: 0.14848069
Q63: INTOWN/DRUID HILLS (Laura, Jordan, Angie, Della, Julie, Ashley) | R63: 24824 | S63: 0.11268373
Q64: SANDY SPRINGS (Allison, Jen, Terri, Sarah, Kate) | R64: 13868 | S64: 0.062951094
Q65: FLOWERY BRANCH (Kristina) | R65: 7026 | S65: 0.031893163
Q66: Collective Learning | R66: 5100 | S66: 0.02315046
Q67: Grand Total | R67: 220298 | S67: 1
